\hypertarget{classgevent_1_1exceptions_1_1_loop_exit}{}\section{gevent.\+exceptions.\+Loop\+Exit Class Reference}
\label{classgevent_1_1exceptions_1_1_loop_exit}\index{gevent.\+exceptions.\+Loop\+Exit@{gevent.\+exceptions.\+Loop\+Exit}}


Inherits Exception.

\subsection*{Public Member Functions}
\begin{DoxyCompactItemize}
\item 
def \hyperlink{classgevent_1_1exceptions_1_1_loop_exit_ac8a83fb10824f6ed41d90616921e31a6}{\+\_\+\+\_\+repr\+\_\+\+\_\+} (self)
\item 
\mbox{\Hypertarget{classgevent_1_1exceptions_1_1_loop_exit_aaf46dfdf21e5d152f69b39d8f9d36f8c}\label{classgevent_1_1exceptions_1_1_loop_exit_aaf46dfdf21e5d152f69b39d8f9d36f8c}} 
def {\bfseries \+\_\+\+\_\+str\+\_\+\+\_\+} (self)
\end{DoxyCompactItemize}


\subsection{Detailed Description}
\begin{DoxyVerb}Exception thrown when the hub finishes running (`gevent.hub.Hub.run`
would return).

In a normal application, this is never thrown or caught
explicitly. The internal implementation of functions like
:meth:`gevent.hub.Hub.join` and :func:`gevent.joinall` may catch it, but user code
generally should not.

.. caution::
   Errors in application programming can also lead to this exception being
   raised. Some examples include (but are not limited too):

   - greenlets deadlocking on a lock;
   - using a socket or other gevent object with native thread
     affinity from a different thread\end{DoxyVerb}
 

\subsection{Member Function Documentation}
\mbox{\Hypertarget{classgevent_1_1exceptions_1_1_loop_exit_ac8a83fb10824f6ed41d90616921e31a6}\label{classgevent_1_1exceptions_1_1_loop_exit_ac8a83fb10824f6ed41d90616921e31a6}} 
\index{gevent\+::exceptions\+::\+Loop\+Exit@{gevent\+::exceptions\+::\+Loop\+Exit}!\+\_\+\+\_\+repr\+\_\+\+\_\+@{\+\_\+\+\_\+repr\+\_\+\+\_\+}}
\index{\+\_\+\+\_\+repr\+\_\+\+\_\+@{\+\_\+\+\_\+repr\+\_\+\+\_\+}!gevent\+::exceptions\+::\+Loop\+Exit@{gevent\+::exceptions\+::\+Loop\+Exit}}
\subsubsection{\texorpdfstring{\+\_\+\+\_\+repr\+\_\+\+\_\+()}{\_\_repr\_\_()}}
{\footnotesize\ttfamily def gevent.\+exceptions.\+Loop\+Exit.\+\_\+\+\_\+repr\+\_\+\+\_\+ (\begin{DoxyParamCaption}\item[{}]{self }\end{DoxyParamCaption})}

\begin{DoxyVerb}Exception thrown when the hub finishes running (`gevent.hub.Hub.run`
would return).

In a normal application, this is never thrown or caught
explicitly. The internal implementation of functions like
:meth:`gevent.hub.Hub.join` and :func:`gevent.joinall` may catch it, but user code
generally should not.

.. caution::
   Errors in application programming can also lead to this exception being
   raised. Some examples include (but are not limited too):

   - greenlets deadlocking on a lock;
   - using a socket or other gevent object with native thread
 affinity from a different thread\end{DoxyVerb}
 

The documentation for this class was generated from the following file\+:\begin{DoxyCompactItemize}
\item 
venv/lib/python3.\+6/site-\/packages/gevent/exceptions.\+py\end{DoxyCompactItemize}
